Workbook
Name bhp: #REF!
Name bht: #REF!
Name Clear_Joblog: #REF!
Name csg: '[1]ATS Report'!#REF!
Name delete: 'DST-2 Calc 17.2 ppg'!delete
Name delete: [0]!delete
Name Delete_Comment: #REF!
Name Final_Joblog: #REF!
Name gas_cumm: '[1]ATS Report'!#REF!
Name gas_time: #REF!
Name gasrate: '[1]ATS Report'!#REF!
Name gor: '[1]ATS Report'!#REF!
Name Insert_Comment: #REF!
Name ogr: '[2]Test Data'!$T$8:$T$16,'[2]Test Data'!$T$18:$T$122,'[2]Test Data'!$T$132:$T$247
Name oil_cumm: '[1]ATS Report'!#REF!
Name oilrate: '[1]ATS Report'!#REF!
Name salinity: '[1]ATS Report'!#REF!
Name sep_press: '[1]ATS Report'!#REF!
Name sep_temp: '[1]ATS Report'!#REF!
Name Set_LOCK_OFF: #REF!
Name Set_WTR_RATE: #REF!
Name ShowDialog: 'DST-2 Calc 17.2 ppg'!ShowDialog
Name ShowDialog: [0]!ShowDialog
Name SORT: #REF!
Name wtr_cumm: '[1]ATS Report'!#REF!
Name wtr_rate: '[1]ATS Report'!#REF!

Sheet DST-2 -XHP Packer
B2: HALLIBURTON TOOL STRING SCHEMATIC WITH 7"# 35 PPF RETRIEVABLE XHP CHAMP PACKER-V
H3: CUSTOMER: | J3: ONGC | L3: TEST: | M3: DST-2 | O3: VERSION:
H4: WELL NAME: | J4: D33#G/ D-33-9 | L4: RIG: | M4: GD Chetna | O4: Final
H5: FORMATION: | J5: Panna/ Sandstone | L5: DATE: | M5: 45046
C6: Description | J6: TOOL NUMBER | K6: COMPANY | L6: BOX | M6: PIN | N6: OD (in) | O6: ID (in) | P6: Length (m) | Q6: Top Of Tool MD (Mtr) | R6: Bottom Of Tool MD (Mtr) | T6: Hydrostatic With 11.6 ppg | U6: Volume | V6: Cum Volume
C7: X-over 7" Bowen BOX X 5-3/4" SA PIN | J7: ` | K7: EXPRO | L7: 7" Bowen | M7: 5 3/4" SA Pin | N7: 7 | O7: 3 | P7: 0.21 | Q7: =Q8-P7 -> -5.98 | R7: =Q7+P7 -> -5.77 | U7: =0.0009714*O7*O7*P7*3.281 -> 0.0060237388 | V7: =U7 -> 0.0060237388
C8: HANDLING SUB | K8: EXPRO | L8: 5-3/4" SA Box | M8: 5 3/4" SA Pin | N8: 5 | O8: 3 | P8: 1.1 | Q8: =Q9-P8 -> -5.77 | R8: =Q8+P8 -> -4.67 | U8: =0.0009714*O8*O8*P8*3.281 -> 0.031552918 | V8: =V7+U8 -> 0.037576656
C9: SURFACE TEST TREE + Master Valve | K9: EXPRO | L9: 5-3/4" SA Box | M9: 5-3/4" SA Pin | N9: N/A | O9: 3 | P9: 2 | Q9: =Q10-P9 -> -4.67 | R9: =Q9+P9 -> -2.67 | U9: =0.0009714*O9*O9*P9*3.281 -> 0.057368941 | V9: =V8+U9 -> 0.094945598
C10: PRESSURE BALANCED SWIVEL | K10: EXPRO | L10: 5-3/4" SA Box | M10: 5-3/4" SA PIN | N10: 20 | O10: 3 | P10: 0.61 | Q10: =Q11-P10 -> -2.67 | R10: =Q10+P10 -> -2.06 | U10: =0.0009714*O10*O10*P10*3.281 -> 0.017497527 | V10: =V9+U10 -> 0.11244312
C11: Saver Sub | K11: EXPRO | L11: 5-3/4" SA Box | M11: 5-3/4" SA BOX | N11: 8 | O11: 3 | P11: 0.46 | Q11: =Q12-P11 -> -2.06 | R11: =Q11+P11 -> -1.6 | U11: =0.0009714*O11*O11*P11*3.281 -> 0.013194856 | V11: =V10+U11 -> 0.12563798
C12: X-Over 5-3/4" SA PIN X 5-3/4" SA PIN | K12: EXPRO | L12: 5-3/4" SA PIN | M12: 5-3/4" SA PIN | N12: 8 | O12: 3 | P12: 0.13 | Q12: =Q13-P12 -> -1.6 | R12: =Q12+P12 -> -1.47 | U12: =0.0009714*O12*O12*P12*3.281 -> 0.0037289812 | V12: =V11+U12 -> 0.12936696
C13: Stiff Joint Expro | I13: RKB | K13: EXPRO | L13: 5-3/4" SA Box | M13: 5-3/4" SA PIN | N13: 8 | O13: 3 | P13: 2.88 | Q13: =Q14-P13 -> -1.47 | R13: =Q13+P13 -> 1.41 | T13: =R13*0.1706*11.6 -> 2.7903336 | U13: =0.0009714*O13*O13*P13*3.281 -> 0.082611275 | V13: =V12+U13 -> 0.21197824
C14: X-Over 5-3/4" SA BOX X 5-3/4" BOX | K14: EXPRO | L14: 5 3/4" SA Box | M14: 5 3/4" SA Box | N14: 8 | O14: 3 | P14: 0.465 | Q14: =Q15-P14 -> 1.41 | R14: =Q14+P14 -> 1.875 | U14: =0.0009714*O14*O14*P14*3.281 -> 0.013338279 | V14: =V13+U14 -> 0.22531652
C15: X-Over 5-3/4" SA PIN X 5-3/4" SA PIN | K15: EXPRO | L15: 5-3/4" SA PIN | M15: 5-3/4" SA PIN | N15: 8 | O15: 2.75 | P15: 0.125 | Q15: =Q16-P15 -> 1.875 | R15: =Q15+P15 -> 2 | U15: =0.0009714*O15*O15*P15*3.281 -> 0.0030128654 | V15: =V14+U15 -> 0.22832938
C16: Stiff Joint Expro | K16: EXPRO | L16: 5-3/4" SA Box | M16: 5-3/4" SA PIN | N16: 8 | O16: 3 | P16: 2.88 | Q16: =Q17-P16 -> 2 | R16: =Q16+P16 -> 4.88 | U16: =0.0009714*O16*O16*P16*3.281 -> 0.082611275 | V16: =V15+U16 -> 0.31094066
C17: X-Over 5-3/4" SA BOX 4-1/2 BGT-2 PIN | K17: EXPRO | L17: 5 3/4" SA Box | M17: 4-1/2 BGT-2 PIN | N17: 8 | O17: 3 | P17: 0.48 | Q17: =Q18-P17 -> 4.88 | R17: =Q17+P17 -> 5.36 | U17: =0.0009714*O17*O17*P17*3.281 -> 0.013768546 | V17: =V16+U17 -> 0.3247092
C18: Pup Joint 4-1/2 # 23.7 PPF BGT -2 ( BOX-X BOX) | K18: ONGC | L18: 4-1/2 BGT-2 BOX | M18: 4-1/2 BGT-2 BOX | N18: 4.5 | O18: 3 | P18: 2.6 | Q18: =Q19-P18 -> 5.36 | R18: =Q18+P18 -> 7.96 | U18: =0.0009714*O18*O18*P18*3.281 -> 0.074579624 | V18: =V17+U18 -> 0.39928883
C19: X-Over X 4-1/2 BGT-2 PIN X 5-3/4" SABOX | K19: EXPRO | L19: 4-1/2 BGT-1 PIN | M19: 5 3/4" SA Box | N19: 8 | O19: 3 | P19: 0.505 | Q19: =Q20-P19 -> 7.96 | R19: =Q19+P19 -> 8.465 | U19: =0.0009714*O19*O19*P19*3.281 -> 0.014485658 | V19: =V18+U19 -> 0.41377448
C20: Stiff Joint Expro | K20: EXPRO | L20: 5 3/4" SA PIN | M20: 5-3/4" SA BOX | N20: 8 | O20: 3 | P20: 1.22 | Q20: =Q21-P20 -> 8.465 | R20: =Q20+P20 -> 9.685 | U20: =0.0009714*O20*O20*P20*3.281 -> 0.034995054 | V20: =V19+U20 -> 0.44876954
C21: X-Over 5-3/4" SA PIN X 5-3/4" SA PIN | K21: HAL | L21: 5-3/4" SA PIN | M21: 5-3/4" SA PIN | N21: 8 | O21: 2.75 | P21: 0.355 | Q21: =Q22-P21 -> 9.685 | R21: =Q21+P21 -> 10.04 | U21: =0.0009714*O21*O21*P21*3.281 -> 0.0085565377 | V21: =V20+U21 -> 0.45732608
C22: SSV Handling Sub | K22: HAL | L22: 5- 3/4" SA Box | M22: 5 " SA PIN | N22: 8 | O22: 3 | P22: 1.63 | Q22: =Q23-P22 -> 10.04 | R22: =Q22+P22 -> 11.67 | U22: =0.0009714*O22*O22*P22*3.281 -> 0.046755687 | V22: =V21+U22 -> 0.50408176
C23: SSV Top to Center of Ramlock 5" OD | K23: HAL | L23: 5 " SA BOX | M23: N/A | N23: 8 | O23: 3 | P23: 0.47 | Q23: =Q24-P23 -> 11.67 | R23: =Q23+P23 -> 12.14 | U23: =0.0009714*O23*O23*P23*3.281 -> 0.013481701 | V23: =V22+U23 -> 0.51756346
C24: SSV Center of Ramlock to Bottom of SSV ( Center Of 5" RAM 12.14 m) | K24: HAL | L24: N/A | M24: 5" 4 ACME BOX | N24: 8 | O24: 3 | P24: 1.525 | Q24: =Q25-P24 -> 12.14 | R24: =Q24+P24 -> 13.665 | T24: =R24*0.1706*11.6 -> 27.042488 | U24: =0.0009714*O24*O24*P24*3.281 -> 0.043743818 | V24: =V23+U24 -> 0.56130728
C25: X-OVER 5"4 ACME PIN X 3 1/2 ABTC-II #15.8 PPF PIN | K25: HAL | L25: 5" 4 ACME PIN | M25: 3-1/2 VAS | N25: 6 | O25: 2.54 | P25: 0.33 | Q25: =Q26-P25 -> 13.665 | R25: =Q25+P25 -> 13.995 | T25: =R25*0.1706*11.6 -> 27.695545 | U25: =0.0009714*O25*O25*P25*3.281 -> 0.0067855601 | V25: =V24+U25 -> 0.56809284
C26: X-OVER 3-1/2 ABTC-II # 15.8 B X 3-7/8 CAS PIN | K26: HAL | L26: 5" 4 ACME PIN | M26: 3-1/2 VAS | N26: 6 | O26: 2.54 | P26: 0.433 | Q26: =Q27-P26 -> 13.995 | R26: =Q26+P26 -> 14.428 | T26: =R26*0.1706*11.6 -> 28.552435 | U26: =0.0009714*O26*O26*P26*3.281 -> 0.0089034774 | V26: =V25+U26 -> 0.57699632
C27: X-OVER 3-7/8 CAS B X 3-1/2" VAS #15.5PPF PIN | K27: HAL | L27: 5" 4 ACME PIN | M27: 3-1/2 VAS | N27: 6 | O27: 2.54 | P27: 0.49 | Q27: =Q28-P27 -> 14.428 | R27: =Q27+P27 -> 14.918 | T27: =R27*0.1706*11.6 -> 29.522125 | U27: =0.0009714*O27*O27*P27*3.281 -> 0.010075529 | V27: =V26+U27 -> 0.58707185
C28: Tubing 3-1/2 VAS #15.5 PPF ( 1 STAND ) | K28: ONGC | L28: 3-1/2 VAS | M28: 3-1/2 VAS | N28: 3.5 | O28: 2.54 | P28: 28.86 | Q28: =Q29-P28 -> 14.918 | R28: =Q28+P28 -> 43.778 | U28: =0.0009714*O28*O28*P28*3.281 -> 0.59342808 | V28: =V26+U28 -> 1.1704244
C29: Pup Joint 3-1/2 VAS #15.5 PPF | K29: ONGC | L29: 3-1/2 VAS | M29: 3-1/2 VAS | N29: 3.5 | O29: 2.54 | P29: 2.35 | Q29: =Q30-P29 -> 43.778 | R29: =Q29+P29 -> 46.128 | U29: =0.0009714*O29*O29*P29*3.281 -> 0.048321413 | V29: =V27+U29 -> 0.63539326
C30: Pup Joint 3-1/2 VAS #15.5 PPF | K30: ONGC | L30: 3-1/2 VAS | M30: 3-1/2 VAS | N30: 3.5 | O30: 2.54 | P30: 2.35 | Q30: =Q31-P30 -> 46.128 | R30: =Q30+P30 -> 48.478 | U30: =0.0009714*O30*O30*P30*3.281 -> 0.048321413 | V30: =V29+U30 -> 0.68371467
C31: Pup Joint 3-1/2 VAS #15.5 PPF | K31: ONGC | L31: 3-1/2 VAS | M31: 3-1/2 VAS | N31: 3.5 | O31: 2.54 | P31: 2.96 | Q31: =Q32-P31 -> 48.478 | R31: =Q31+P31 -> 51.438 | U31: =0.0009714*O31*O31*P31*3.281 -> 0.060864418 | V31: =V30+U31 -> 0.74457909
C32: Tubing 3-1/2 VAS #15.5 PPF ( 92 STANDS + 1 single ) | K32: ONGC | L32: 3-1/2 VAS | M32: 3-1/2 VAS | N32: 3.5 | O32: 2.54 | P32: 2670.216 | Q32: =Q33-P32 -> 51.438 | R32: =Q32+P32 -> 2721.654 | T32: =R32*0.1706*11.6 -> 5386.0444 | U32: =0.0009714*O32*O32*P32*3.281 -> 54.905792 | V32: =V31+U32 -> 55.650371
C33: X-OVER 3-1/2" VAS B #15.5 PPF B X 3 -7/8 CAS P | K33: HAL | L33: 3-1/2 VAS | M33: 3-7/8 CAS P | N33: 5 | O33: 2.25 | P33: 0.4 | Q33: =Q34-P33 -> 2721.654 | R33: =Q33+P33 -> 2722.054 | U33: =0.0009714*O33*O33*P33*3.281 -> 0.0064540059 | V33: =V32+U33 -> 55.656825
C34: RA SUB (RA Marker @2719.66 m) | H34: Top | K34: HAL | L34: 3 7/8 CAS B | M34: 3 7/8 CAS P | N34: 5 | O34: 2.25 | P34: 0.2 | Q34: =Q35-P34 -> 2722.054 | R34: =Q34+P34 -> 2722.254 | T34: =R34*0.1706*11.6 -> 5387.2318 | U34: =0.0009714*O34*O34*P34*3.281 -> 0.0032270029 | V34: =V33+U34 -> 55.660052
H35: Bottom | K35: HAL | P35: 0.1 | Q35: =Q36-P35 -> 2722.254 | R35: =Q35+P35 -> 2722.354 | T35: =R35*0.1706*11.6 -> 5387.4297 | U35: =0.0009714*O35*O35*P35*3.281 -> 0 | V35: =V34+U35 -> 55.660052
C36: RM Slip Joint / Close | K36: HAL | L36: 3 7/8'' CAS | M36: 3 7/8'' CAS | N36: 5 | O36: 2.25 | P36: 4.6 | Q36: =Q37-P36 -> 2722.354 | R36: =Q36+P36 -> 2726.954 | U36: =0.0009714*O36*O36*P36*3.281 -> 0.074221068 | V36: =V35+U36 -> 55.734273
C37: RM Slip Joint / Close | K37: HAL | L37: 3 7/8'' CAS | M37: 3 7/8'' CAS | N37: 5 | O37: 2.25 | P37: 5.01 | Q37: =Q38-P37 -> 2726.954 | R37: =Q37+P37 -> 2731.964 | U37: =0.0009714*O37*O37*P37*3.281 -> 0.080836424 | V37: =V36+U37 -> 55.815109
C38: RM Slip Joint / Open | K38: HAL | L38: 3 7/8'' CAS | M38: 3 7/8'' CAS | N38: 5 | O38: 2.25 | P38: 6.1 | Q38: =Q39-P38 -> 2731.964 | R38: =Q38+P38 -> 2738.064 | U38: =0.0009714*O38*O38*P38*3.281 -> 0.09842359 | V38: =V37+U38 -> 55.913533
C39: RM Slip Joint / Open | K39: HAL | L39: 3 7/8'' CAS | M39: 3 7/8'' CAS | N39: 5 | O39: 2.25 | P39: 6.1 | Q39: =Q40-P39 -> 2738.064 | R39: =Q39+P39 -> 2744.164 | U39: =0.0009714*O39*O39*P39*3.281 -> 0.09842359 | V39: =V38+U39 -> 56.011956
C40: X-OVER 3 -7/8 CAS B X 3-1/2" VAS #15.5 PPF P | K40: HAL | L40: 3 7/8'' CAS | M40: 3-1/2 VAS | N40: 5 | O40: 2.25 | P40: 0.48 | Q40: =Q41-P40 -> 2744.164 | R40: =Q40+P40 -> 2744.644 | U40: =0.0009714*O40*O40*P40*3.281 -> 0.0077448071 | V40: =V39+U40 -> 56.019701
C41: 3-1/2" VAS # 15.5 PPF Tubing (33 STANDS) | K41: ONGC | L41: 3-1/2 VAS | M41: 3-1/2 VAS | N41: 3.5 | O41: 2.54 | P41: 947.06 | Q41: =Q42-P41 -> 2744.644 | R41: =Q41+P41 -> 3691.704 | U41: =0.0009714*O41*O41*P41*3.281 -> 19.473735 | V41: =V40+U41 -> 75.493436
...

Sheet DST-2  Calc 17.2 ppg
C4: PREPARED BY | E4: Avinash Negi | H4: VERSION | I4: DST 2 | K4: DATE | N4: 45046
A5: ONGC - Offshore
C6: START DATE | E6: =N4 -> 45046 | G6: WELL NAME | I6: D-33#G | L6: LOCATION | N6: Offshore
C7: CLIENT | E7: ONGC | G7: FIELD / LEASE | I7: Mumbai Offshore | L7: RIG TYPE | N7: Jack Up
C8: RIG NAME | E8: GD Chetna | F8: Kill FLUID | I8: 17.2 PPG SOBM | L8: JOB | N8: =I4 -> DST 2
B9: SURFACE TEMPERATURE | E9: 90.0 ⁰F | F9: DOWNHOLE TEMPERATURE | I9: 340.0 ⁰F | K9: FLUID DENSITY | N9: 17.2 PPG Calcium Bromide + Micromax
D11: CASING LIMIT | F11: 4,425 psi
A14: RD SAFETY CIRCULATING VALVE | K14: Notes:
E15: Fluid Weight Used ( ppg ) | F15: 17.2
E16: Tool Depth TVD ( Mtr ) | F16: ='DST-2 -XHP Packer'!R45 -> 3694.134
E17: Hydrostatic Pressure ( Psi) | F17: =F16*3.281*F15*0.052 -> 10840.534
E18: Rupture Disk Burst Value ( Psi ) | F18: 15 K
E19: Temperature Corrected (Psi) | F19: 14900
E20: Surface operating pressure(Psi) | F20: =F19-F17 -> 4059.4663
E21: 2% High | 2% Low (Psi) | F21: =F19+(F19*0.02)-F17 -> 4357.4663 | G21: =F19-(F19*0.02)-F17 -> 3761.4663
E24: RD TST Tubing Tester Valve - 4 PINS:
E26: Bottom Hole Temp ( Deg F ) : | F26: 380 | H26: 380
E27: Fluid Weight Used ( #g ) : | F27: 15.7 | H27: 15.7
E28: Tool Depth TVD ( Mtr ) : | F28: 4360.38 | H28: 4360.38
E29: Hydrostatic Pressure ( Psi): | F29: =F28*3.281*F27*0.052 -> 11679.75 | H29: =H28*3.281*H27*0.052 -> 11679.75
E30: Rupture Disk Burst Value ( Psi ) : | F30: 13.5 | H30: 13.5
E31: Temperature Correted (Psi): | F31: 13100 | H31: 13100
E32: Surface operating pressure(Psi): | F32: =F31-F29 -> 1420.2495 | H32: =H31-H29 -> 1420.2495
E33: 2% High / 2% Low (Psi): | F33: =F31+(F31*0.02)-F29 -> 1682.2495 | G33: =F31-(F31*0.02)-F29 -> 1158.2495 | H33: =H31+(H31*0.02)-H29 -> 1682.2495 | I33: =H31-(H31*0.02)-H29 -> 1158.2495
A35: OMNI CIRCULATING VALVE - DOUBLE CHAMBER | K35: Notes:
C36: Fluid Weight Used ( ppg ) : | F36: 17.2 | K36: 1. N2 Reduction Factor @ 91%. 2. N2 charging pressure base on Single Chamber Charge. 3. Operating pressure as per N2 Calculator 1220 psi.
C37: Tool Depth TVD ( Mtr ) : | F37: ='DST-2 -XHP Packer'!R48 -> 3705.412
C38: Hydrostatic Pressure ( Psi): | F38: =F37*3.281*F36*0.052 -> 10873.629
C39: Nitrogen Charge Pressure( Psi): | F39: 5900
C40: Piston Position Results - Operating: | F40: 19% -37%
C41: Surface operating pressure(Psi): | F41: 1400
C42: Tool Run Positon: | F42: 2.5 | G42: Well Test
E44: SELECT Tester Valve
E46: Bottom Hole Temp ( Deg F ) : | F46: 382 | H46: 382
E47: Fluid Weight Used ( #g ) : | F47: 15.3 | H47: 15.3
E48: Tool Depth TVD ( Mtr ) : | F48: 4999 | H48: 4999
E49: Hydrostatic Pressure ( Psi): | F49: =F48*3.281*F47*0.052 -> 13049.208 | H49: =H48*3.281*H47*0.052 -> 13049.208
E50: Nitrogen Charge Pressure( Psi): | F50: 6217 | H50: 6217
E51: Surface operating pressure(Psi): | F51: 1438 | H51: 1438
E52: Lock Open Operation Pressure (Psi): | F52: 2738 | H52: 2738
...
